<?xml version="1.0" ?>
<robot name="ros_robot" xmlns:xacro="http://www.ros.org/wiki/xacro" >

<link name="BackThrusterL_1">
  <inertial>
    <origin xyz="-0.00679269338143873 2.1826941126734667e-07 -0.15892739606734135" rpy="0 0 0"/>
    <mass value="1.9708306012870964"/>
    <inertia ixx="0.011921" iyy="0.012132" izz="0.000443" ixy="-0.0" iyz="-0.0" ixz="0.000811"/>
  </inertial>
  <visual>
    <origin xyz="0.515514 -0.150104 -0.279079" rpy="0 0 0"/>
    <geometry>
      <mesh filename="package://ros_robot_description/meshes/BackThrusterL_1.stl" scale="0.001 0.001 0.001"/>
    </geometry>
    <material name="paint_enamel_glossy_red"/>
  </visual>

  <collision>
    <origin xyz="0.515514 -0.150104 -0.279079" rpy="0 0 0"/>
    <geometry>
      <mesh filename="package://ros_robot_description/meshes/BackThrusterL_1.stl" scale="0.001 0.001 0.001"/>
    </geometry>
  </collision>
</link>

<link name="BackPropellerL_1">
  <inertial>
    <origin xyz="-0.02691605112418549 -6.697354491103091e-06 -1.4490021561459898e-05" rpy="0 0 0"/>
    <mass value="0.6485270682886274"/>
    <inertia ixx="0.000738" iyy="0.000497" izz="0.000497" ixy="0.0" iyz="0.0" ixz="-0.0"/>
  </inertial>
  <visual>
    <origin xyz="0.555119 -0.150104 -0.022079" rpy="0 0 0"/>
    <geometry>
      <mesh filename="package://ros_robot_description/meshes/BackPropellerL_1.stl" scale="0.001 0.001 0.001"/>
    </geometry>
    <material name="abs_white"/>
  </visual>
  <collision>
    <origin xyz="0.555119 -0.150104 -0.022079" rpy="0 0 0"/>
    <geometry>
      <mesh filename="package://ros_robot_description/meshes/BackPropellerL_1.stl" scale="0.001 0.001 0.001"/>
    </geometry>
  </collision>
</link>

<joint name="BackThrusterL" type="revolute">
  <origin xyz="-0.515514 0.150104 0.279079" rpy="0 0 0"/>
  <axis xyz="0.0 0.0 -1.0"/>
  <parent link="base_link"/>
  <child link="BackThrusterL_1"/>
  <limit effort="10" lower="-3.141592653589793" upper="3.141592653589793" velocity="10"/>
</joint>
<!--for unknown reason, cant turn prop-->
<joint name="BackThrusterLProp" type="continuous">
  <origin xyz="-0.039605 0.0 -0.257" rpy="0 0 0"/>
  <parent link="BackThrusterL_1"/>
  <child link="BackPropellerL_1"/>
  <axis xyz="-1.0 0.0 0.0"/>
  <limit effort="100" velocity="100"/>
  <dynamics damping="0.05" friction="0.05"/>
</joint>

<gazebo reference="BackPropellerL_1">
  <material>Gazebo/Grey</material>
  <mu1>0.2</mu1>
  <mu2>0.2</mu2>
  <selfCollide>true</selfCollide>
</gazebo>

<gazebo reference="BackThrusterL_1">
  <material>Gazebo/Red</material>
  <mu1>0.02</mu1>
  <mu2>0.02</mu2>
  <selfCollide>true</selfCollide>
</gazebo>


</robot>
