<?xml version="1.0" ?>
<robot name="ros_robot" xmlns:xacro="http://www.ros.org/wiki/xacro" >

<link name="CenterThruster_1">
  <inertial>
    <origin xyz="-0.011171969587361441 2.2249469140611026e-07 -0.0643616955563667" rpy="0 0 0"/>
    <mass value="1.1982535523983007"/>
    <inertia ixx="0.001394" iyy="0.001546" izz="0.000303" ixy="-0.0" iyz="-0.0" ixz="8.2e-05"/>
  </inertial>
  <visual>
    <origin xyz="-0.304045 -0.000104 -0.010094" rpy="0 0 0"/>
    <geometry>
      <mesh filename="package://ros_robot_description/meshes/CenterThruster_1.stl" scale="0.001 0.001 0.001"/>
    </geometry>
    <material name="paint_enamel_glossy_red"/>
  </visual>
<!--
  <collision name="left_engine_vertical_axis_collision">
      <origin rpy="0 0 0" xyz="0 0 -0.24"/>
      <geometry>
        <box size="0.2 0.15 0.2"/>
      </geometry>
    </collision>

  <collision>
    <origin xyz="-0.304045 -0.000104 -0.010094" rpy="0 0 0"/>
    <geometry>
      <mesh filename="package://ros_robot_description/meshes/CenterThruster_1.stl" scale="0.001 0.001 0.001"/>
    </geometry>
  </collision>
-->
</link>

<link name="CenterPropeller_1">
  <inertial>
    <origin xyz="-0.028395303528591626 -6.693132053848039e-06 -1.4004445823653788e-05" rpy="0 0 0"/>
    <mass value="0.6485270682886274"/>
    <inertia ixx="0.000738" iyy="0.000497" izz="0.000497" ixy="0.0" iyz="0.0" ixz="-0.0"/>
  </inertial>
  <visual>
    <origin xyz="-0.26444 -0.000104 0.097906" rpy="0 0 0"/>
    <geometry>
      <mesh filename="package://ros_robot_description/meshes/CenterPropellerR_1.stl" scale="0.001 0.001 0.001"/>
    </geometry>
    <material name="abs_white"/>
  </visual>
<!--
  <collision name="left_propeller_collision">
    <origin rpy="0 1.57 0" xyz="0 0 0"/>
    <geometry>
      <cylinder length="0.18" radius="0.08"/>
    </geometry>
  </collision>
  -->
  <collision>
    <origin xyz="-0.26444 -0.000104 0.097906" rpy="0 0 0"/>
    <geometry>
      <mesh filename="package://ros_robot_description/meshes/CenterPropellerR_1.stl" scale="0.001 0.001 0.001"/>
    </geometry>
  </collision>

</link>


<joint name="CenterThruster" type="revolute">
  <axis xyz="0.0 0.0 -1.0"/>
  <origin xyz="0.304045 0.000104 0.010094" rpy="0 0 0"/>
  <parent link="base_link"/>
  <child link="CenterThruster_1"/>
  <limit effort="10" lower="-3.141592653589793" upper="3.141592653589793" velocity="10"/>
</joint>

<joint name="CenterThrusterProp" type="continuous">
  <axis xyz="-1.0 0.0 -0.0"/>
  <origin xyz="-0.039605 0.0 -0.108" rpy="0 0 0"/>
  <parent link="CenterThruster_1"/>
  <child link="CenterPropeller_1"/>
  <limit effort="100" velocity="100"/>
  <dynamics damping="0.05" friction="0.05"/>
</joint>

<gazebo reference="CenterPropeller_1">
  <material>Gazebo/Grey</material>
  <mu1>0.2</mu1>
  <mu2>0.2</mu2>
  <selfCollide>false</selfCollide>
</gazebo>

<gazebo reference="CenterThruster_1">
  <material>Gazebo/Red</material>
  <mu1>0.02</mu1>
  <mu2>0.02</mu2>
  <selfCollide>false</selfCollide>
</gazebo>


</robot>
