<?xml version="1.0" ?>
<robot name="ros_robot" xmlns:xacro="http://www.ros.org/wiki/xacro" >
<link name="ArmBase_1">
  <inertial>
    <origin xyz="0.0011454041878000698 0.0011459188982486657 0.030935981147480862" rpy="0 0 0"/>
    <mass value="23.097311942049508"/>
    <inertia ixx="0.093308" iyy="0.093308" izz="0.170178" ixy="0.002057" iyz="-0.000107" ixz="-0.000107"/>
  </inertial>
  <visual>
    <origin xyz="0.285941 -0.000104 -0.346" rpy="0 0 0"/>
    <geometry>
      <mesh filename="package://ros_robot_description/meshes/ArmBase_1.stl" scale="0.001 0.001 0.001"/>
    </geometry>
    <material name="paint_enamel_glossy_black"/>
  </visual>
  <collision>
    <origin xyz="0.285941 -0.000104 -0.346" rpy="0 0 0"/>
    <geometry>
      <mesh filename="package://ros_robot_description/meshes/ArmBase_1.stl" scale="0.001 0.001 0.001"/>
    </geometry>
  </collision>
</link>

<link name="JawL_1">
  <inertial>
    <origin xyz="-0.03189029458894865 0.010364926026270288 -0.02669858127536817" rpy="0 0 0"/>
    <mass value="0.0018"/>
    <inertia ixx="7e-05" iyy="0.000135" izz="9.2e-05" ixy="1.7e-05" iyz="-1.4e-05" ixz="6.3e-05"/>
  </inertial>
  <visual>
    <origin xyz="0.568431 0.078647 -0.714234" rpy="0 0 0"/>
    <geometry>
      <mesh filename="package://ros_robot_description/meshes/JawL_1.stl" scale="0.001 0.001 0.001"/>
    </geometry>
    <material name="aluminum_anodized_glossy_blue"/>
  </visual>
  <collision>
    <origin xyz="0.568431 0.078647 -0.714234" rpy="0 0 0"/>
    <geometry>
      <mesh filename="package://ros_robot_description/meshes/JawL_1.stl" scale="0.001 0.001 0.001"/>
    </geometry>
  </collision>
</link>

<link name="JawR_1">
  <inertial>
    <origin xyz="-0.031644148141077966 -0.010806778264657124 -0.026615162656639213" rpy="0 0 0"/>
    <mass value="0.0018"/>
    <inertia ixx="7e-05" iyy="0.000133" izz="9.1e-05" ixy="-1.7e-05" iyz="1.5e-05" ixz="6.3e-05"/>
  </inertial>
  <visual>
    <origin xyz="0.569079 -0.014621 -0.714234" rpy="0 0 0"/>
    <geometry>
      <mesh filename="package://ros_robot_description/meshes/JawR_1.stl" scale="0.001 0.001 0.001"/>
    </geometry>
    <material name="aluminum_anodized_glossy_blue"/>
  </visual>
  <collision>
    <origin xyz="0.569079 -0.014621 -0.714234" rpy="0 0 0"/>
    <geometry>
      <mesh filename="package://ros_robot_description/meshes/JawR_1.stl" scale="0.001 0.001 0.001"/>
    </geometry>
  </collision>
</link>

<link name="L6_1">
  <inertial>
    <origin xyz="-0.00803331842765087 -5.6862213045037746e-05 -0.006308097141295432" rpy="0 0 0"/>
    <mass value="0.0018"/>
    <inertia ixx="0.000849" iyy="0.000137" izz="0.000847" ixy="5e-06" iyz="0.0" ixz="2e-06"/>
  </inertial>
  <visual>
    <origin xyz="0.55862 0.032193 -0.722736" rpy="0 0 0"/>
    <geometry>
      <mesh filename="package://ros_robot_description/meshes/L6_1.stl" scale="0.001 0.001 0.001"/>
    </geometry>
    <material name="paint_enamel_glossy_black"/>
  </visual>
  <collision>
    <origin xyz="0.55862 0.032193 -0.722736" rpy="0 0 0"/>
    <geometry>
      <mesh filename="package://ros_robot_description/meshes/L6_1.stl" scale="0.001 0.001 0.001"/>
    </geometry>
  </collision>
</link>

<link name="L5_1">
  <inertial>
    <origin xyz="-0.036796724882995124 -0.017742007672748007 -0.0309788762675699" rpy="0 0 0"/>
    <mass value="0.0018"/>
    <inertia ixx="0.00089" iyy="0.001035" izz="0.00093" ixy="-7e-06" iyz="6e-06" ixz="0.000115"/>
  </inertial>
  <visual>
    <origin xyz="0.494564 0.014147 -0.77659" rpy="0 0 0"/>
    <geometry>
      <mesh filename="package://ros_robot_description/meshes/L5_1.stl" scale="0.001 0.001 0.001"/>
    </geometry>
    <material name="paint_enamel_glossy_black"/>
  </visual>
  <collision>
    <origin xyz="0.494564 0.014147 -0.77659" rpy="0 0 0"/>
    <geometry>
      <mesh filename="package://ros_robot_description/meshes/L5_1.stl" scale="0.001 0.001 0.001"/>
    </geometry>
  </collision>
</link>

<link name="L4_1">
  <inertial>
    <origin xyz="-0.07130925015296014 -0.0004956819947762731 3.779030740558298e-07" rpy="0 0 0"/>
    <mass value="0.0018"/>
    <inertia ixx="0.001409" iyy="0.00355" izz="0.003934" ixy="-1.5e-05" iyz="0.0" ixz="0.0"/>
  </inertial>
  <visual>
    <origin xyz="0.386376 0.031395 -0.77659" rpy="0 0 0"/>
    <geometry>
      <mesh filename="package://ros_robot_description/meshes/L4_1.stl" scale="0.001 0.001 0.001"/>
    </geometry>
    <material name="paint_enamel_glossy_black"/>
  </visual>
  <collision>
    <origin xyz="0.386376 0.031395 -0.77659" rpy="0 0 0"/>
    <geometry>
      <mesh filename="package://ros_robot_description/meshes/L4_1.stl" scale="0.001 0.001 0.001"/>
    </geometry>
  </collision>
</link>

<link name="L3_1">
  <inertial>
    <origin xyz="-0.03328919185654228 -0.028027880306747386 0.029701409398983136" rpy="0 0 0"/>
    <mass value="0.0018"/>
    <inertia ixx="0.005791" iyy="0.022845" izz="0.021796" ixy="-0.000731" iyz="-0.000651" ixz="-0.001282"/>
  </inertial>
  <visual>
    <origin xyz="0.205795 -0.000662 -0.74059" rpy="0 0 0"/>
    <geometry>
      <mesh filename="package://ros_robot_description/meshes/L3_1.stl" scale="0.001 0.001 0.001"/>
    </geometry>
    <material name="paint_enamel_glossy_black"/>
  </visual>
  <collision>
    <origin xyz="0.205795 -0.000662 -0.74059" rpy="0 0 0"/>
    <geometry>
      <mesh filename="package://ros_robot_description/meshes/L3_1.stl" scale="0.001 0.001 0.001"/>
    </geometry>
  </collision>
</link>

<link name="L2_1">
  <inertial>
    <origin xyz="0.07950139518636501 0.029355377391545236 0.07574626013664454" rpy="0 0 0"/>
    <mass value="0.0018"/>
    <inertia ixx="0.022491" iyy="0.044645" izz="0.022859" ixy="-4.4e-05" iyz="8.9e-05" ixz="0.021449"/>
  </inertial>
  <visual>
    <origin xyz="0.40378 0.000715 -0.5426" rpy="0 0 0"/>
    <geometry>
      <mesh filename="package://ros_robot_description/meshes/L2_1.stl" scale="0.001 0.001 0.001"/>
    </geometry>
    <material name="paint_enamel_glossy_black"/>
  </visual>
  <collision>
    <origin xyz="0.40378 0.000715 -0.5426" rpy="0 0 0"/>
    <geometry>
      <mesh filename="package://ros_robot_description/meshes/L2_1.stl" scale="0.001 0.001 0.001"/>
    </geometry>
  </collision>
</link>

<link name="L1_1">
  <inertial>
    <origin xyz="-0.04661521084736314 -0.003531900009707762 0.05173767169330279" rpy="0 0 0"/>
    <mass value="0.0018"/>
    <inertia ixx="0.031917" iyy="0.062523" izz="0.04245" ixy="-0.00181" iyz="-0.001638" ixz="-0.023928"/>
  </inertial>
  <visual>
    <origin xyz="0.285941 -0.000104 -0.4306" rpy="0 0 0"/>
    <geometry>
      <mesh filename="package://ros_robot_description/meshes/L1_1.stl" scale="0.001 0.001 0.001"/>
    </geometry>
    <material name="paint_enamel_glossy_black"/>
  </visual>
  <collision>
    <origin xyz="0.285941 -0.000104 -0.4306" rpy="0 0 0"/>
    <geometry>
      <mesh filename="package://ros_robot_description/meshes/L1_1.stl" scale="0.001 0.001 0.001"/>
    </geometry>
  </collision>
</link>

<joint name="JawL" type="prismatic">
  <origin xyz="-0.009811 -0.046454 -0.008502" rpy="0 0 0"/>
  <parent link="L6_1"/>
  <child link="JawL_1"/>
  <axis xyz="0.0 0.999966 -0.008286"/>
  <limit upper="0.005" lower="-0.003" effort="100" velocity="100"/>
</joint>

<joint name="JawR" type="prismatic">
  <origin xyz="-0.010459 0.046814 -0.008502" rpy="0 0 0"/>
  <parent link="L6_1"/>
  <child link="JawR_1"/>
  <axis xyz="0.0 0.999966 -0.008286"/>
  <limit upper="0.0021" lower="-0.005" effort="100" velocity="100"/>
</joint>

<joint name="L6" type="revolute">
  <origin xyz="-0.064056 -0.018046 -0.053854" rpy="0 0 0"/>
  <parent link="L5_1"/>
  <child link="L6_1"/>
  <axis xyz="-0.766026 -0.005327 -0.642788"/>
  <limit upper="3.141593" lower="-3.141593" effort="100" velocity="100"/>
</joint>

<joint name="L5" type="revolute">
  <origin xyz="-0.108188 0.017248 0.0" rpy="0 0 0"/>
  <parent link="L4_1"/>
  <child link="L5_1"/>
  <axis xyz="-0.006953 0.999976 -0.0"/>
  <limit upper="2.617994" lower="-1.308997" effort="100" velocity="100"/>
</joint>

<joint name="L4" type="revolute">
  <origin xyz="-0.180581 -0.032057 0.036" rpy="0 0 0"/>
  <parent link="L3_1"/>
  <child link="L4_1"/>
  <axis xyz="-0.999976 -0.006953 0.0"/>
  <limit upper="3.141593" lower="-3.141593" effort="100" velocity="100"/>
</joint>

<joint name="L3" type="revolute">
  <origin xyz="0.197985 0.001377 0.19799" rpy="0 0 0"/>
  <parent link="L2_1"/>
  <child link="L3_1"/>
  <axis xyz="0.006953 -0.999976 0.0"/>
  <limit upper="0.610865" lower="-4.101524" effort="100" velocity="100"/>
</joint>

<joint name="L2" type="revolute">
  <origin xyz="-0.117839 -0.000819 0.112" rpy="0 0 0"/>
  <parent link="L1_1"/>
  <child link="L2_1"/>
  <axis xyz="-0.006953 0.999976 -0.0"/>
  <limit upper="1.134464" lower="-3.490659" effort="100" velocity="100"/>

  <dynamics damping="100.0" friction="100.0"/>  <!--fjern denne, kun for å holde armen i ro når ingen controller -->
</joint>

<joint name="L1" type="revolute">
  <origin xyz="0.0 0.0 0.0856" rpy="0 0 0"/>
  <parent link="ArmBase_1"/>
  <child link="L1_1"/>
  <axis xyz="0.0 0.0 1.0"/>
  <limit upper="2.181662" lower="-2.181662" effort="100" velocity="100"/>
</joint>

<joint name="ArmBaseLink" type="fixed">
  <origin xyz="-0.285941 0.000104 0.346" rpy="0 0 0"/>
  <parent link="base_link"/>
  <child link="ArmBase_1"/>
</joint>


</robot>
